Workbook

Sheet AR_Input
B1: RIGHT EYE | E1: LEFT EYE
B2: S | C2: C | D2: A | E2: S | F2: C | G2: A
A3: visit_id | B3: S_r_AR | C3: C_r_AR | D3: A_r_AR | E3: S_l_AR | F3: C_l_AR | G3: A_l_AR
A4: 1 | B4: -2.5 | C4: -1.75 | D4: 90 | E4: -2.5 | F4: -3.75 | G4: 70
A5: 2 | B5: -0.5 | C5: -0.75 | D5: 50 | E5: -0.25 | F5: -1 | G5: 60
A6: 3 | B6: -2.5 | C6: -1 | D6: 80 | E6: -4 | F6: -0.5 | G6: 40
A7: 4 | B7: -4 | C7: -2.5 | D7: 20 | E7: -3.75 | F7: -2.5 | G7: 160
A8: 5 | B8: -2.75 | C8: -0.75 | E8: -3 | F8: -0.5
A9: 6 | B9: -1.5 | C9: -0.5 | E9: -1 | F9: 0 | G9: 0

Sheet Lenso_Input
B1: RIGHT EYE | F1: LEFT EYE
B2: S | C2: C | D2: A | E2: Add | F2: S | G2: C | H2: A | I2: Add
A3: visit_id | B3: S_r_Lenso | C3: C_r_Lenso | D3: A_r_Lenso | E3: Add_r_Lenso | F3: S_l_Lenso | G3: C_l_Lenso | H3: A_l_Lenso | I3: Add_l_Lenso
A4: 1 | B4: -3 | C4: -2 | D4: 70 | E4: 2.5 | F4: -2.5 | G4: -1.5 | H4: 90 | I4: -2
A5: 2
A6: 3 | B6: -2 | C6: -0.75 | D6: 70 | F6: -3.25 | G6: 0 | H6: 0
A7: 4 | B7: -3.5 | C7: -2 | D7: 10 | F7: -3.25 | G7: -2 | H7: 170
A8: 5 | B8: -2.5 | C8: -0.5 | F8: -2.75 | G8: -0.25

Sheet Patient_Input_Master
A1: Section | B1: Field Name | C1: Value (enter here) | D1: Data Type | E1: Allowed Values / Format | F1: Required | G1: Notes
A2: A) IDENTIFIERS & SESSION CONTEXT | B2: patient_id | D2: String | E2: Unique ID | F2: Yes | G2: Persistent across visits
A3: A) IDENTIFIERS & SESSION CONTEXT | B3: visit_id | D3: String | E3: Unique ID | F3: Yes | G3: Unique per test session
A4: A) IDENTIFIERS & SESSION CONTEXT | B4: test_date_time | D4: Datetime | E4: ISO 8601 | F4: Yes | G4: Timestamp of exam
A5: B) DEMOGRAPHICS & USAGE PROFILE | B5: age_years | D5: Integer | E5: ≥ 3 | F5: Yes | G5: Drives presbyopia logic
A6: B) DEMOGRAPHICS & USAGE PROFILE | B6: gender | D6: Enum | E6: See dropdown | F6: Yes
A7: B) DEMOGRAPHICS & USAGE PROFILE | B7: lifestyle | D7: Enum | E7: See dropdown | F7: Yes | G7: Influences endpoint bias
A8: B) DEMOGRAPHICS & USAGE PROFILE | B8: occupation_type | D8: Enum | F8: Yes | G8: Determines visual priority
A9: B) DEMOGRAPHICS & USAGE PROFILE | B9: screen_time_hours | D9: Float | E9: 0–24 | F9: Yes | G9: Daily average
A10: B) DEMOGRAPHICS & USAGE PROFILE | B10: driving_time_hours | D10: Float | E10: 0–24 | F10: Yes | G10: Daily average
A11: C) REASON FOR VISIT & SYMPTOMS | B11: primary_reason | D11: Enum | E11: See dropdown | F11: Yes | G11: Single select
A12: C) REASON FOR VISIT & SYMPTOMS | B12: symptoms_multi | D12: Multi-Enum | E12: Comma-separated OR pick one | F12: No | G12: Excel dropdown enforces single choice; for multi-select enter comma-separated values
A13: D) CURRENT EYEWEAR & ADAPTATION | B13: currently_wearing_glasses | D13: Boolean | E13: True / False | F13: Yes
A14: D) CURRENT EYEWEAR & ADAPTATION | B14: wear_type | D14: Enum | E14: See dropdown | F14: Yes
A15: D) CURRENT EYEWEAR & ADAPTATION | B15: wear_duration_months | D15: Integer | E15: ≥ 0 | F15: No | G15: Duration of current RX
A16: D) CURRENT EYEWEAR & ADAPTATION | B16: satisfaction_with_current_rx | D16: Enum | E16: See dropdown | F16: Yes | G16: Drives start policy
A17: D) CURRENT EYEWEAR & ADAPTATION | B17: main_complaint_current_rx | D17: Multi-Enum | E17: Comma-separated OR pick one | F17: No | G17: Excel dropdown enforces single choice; for multi-select enter comma-separated values
A18: E) RECENCY & STABILITY INDICATORS | B18: last_eye_test_months_ago | D18: Integer | E18: ≥ 0 | F18: No
A19: E) RECENCY & STABILITY INDICATORS | B19: rx_change_last_time_known | D19: Boolean | E19: True / False | F19: No
A20: E) RECENCY & STABILITY INDICATORS | B20: rx_change_was_large | D20: Boolean | E20: True / False | F20: No | G20: Define threshold internally
A21: E) RECENCY & STABILITY INDICATORS | B21: fluctuating_vision_reported | D21: Boolean | E21: True / False | F21: No | G21: Anomaly trigger
A22: F) MEDICAL & OCULAR HISTORY | B22: diabetes | D22: Boolean | E22: True / False | F22: Yes | G22: Stability impact
A23: F) MEDICAL & OCULAR HISTORY | B23: hypertension | D23: Boolean | E23: True / False | F23: No
A24: F) MEDICAL & OCULAR HISTORY | B24: thyroid_disorder | D24: Boolean | E24: True / False | F24: No
A25: F) MEDICAL & OCULAR HISTORY | B25: prior_eye_surgery | D25: Enum | E25: See dropdown | F25: Yes
A26: F) MEDICAL & OCULAR HISTORY | B26: known_keratoconus | D26: Boolean | E26: True / False | F26: Yes
A27: F) MEDICAL & OCULAR HISTORY | B27: known_amblyopia | D27: Boolean | E27: True / False | F27: Yes
A28: F) MEDICAL & OCULAR HISTORY | B28: current_eye_infection_or_inflammation | D28: Boolean | E28: True / False | F28: Yes | G28: Safety flag
A29: G) PATIENT PREFERENCE & OUTCOME TARGET | B29: priority | D29: Enum | E29: See dropdown | F29: Yes | G29: Endpoint bias
A30: G) PATIENT PREFERENCE & OUTCOME TARGET | B30: distance_target | D30: Enum | E30: See dropdown | F30: Yes | G30: Target acuity
A31: G) PATIENT PREFERENCE & OUTCOME TARGET | B31: near_priority | D31: Enum | E31: See dropdown | F31: Yes | G31: Near workflow

Sheet Patient_Input_Data
A1: IDENTIFIERS & SESSION CONTEXT | D1: DEMOGRAPHICS & USAGE PROFILE | J1: REASON FOR VISIT & SYMPTOMS | L1: CURRENT EYEWEAR & ADAPTATION | Q1: RECENCY & STABILITY INDICATORS | U1: MEDICAL & OCULAR HISTORY | AB1: PATIENT PREFERENCE & OUTCOME TARGET
A2: patient_id | B2: visit_id | C2: test_date_time | D2: age_years | E2: gender | F2: lifestyle | G2: occupation_type | H2: screen_time_hours | I2: driving_time_hours | J2: primary_reason | K2: symptoms_multi | L2: currently_wearing_glasses | M2: wear_type | N2: wear_duration_months | O2: satisfaction_with_current_rx | P2: main_complaint_current_rx | Q2: last_eye_test_months_ago | R2: rx_change_last_time_known | S2: rx_change_was_large | T2: fluctuating_vision_reported | U2: diabetes | V2: hypertension | W2: thyroid_disorder | X2: prior_eye_surgery | Y2: known_keratoconus | Z2: known_amblyopia | AA2: current_eye_infection_or_inflammation | AB2: priority | AC2: distance_target | AD2: near_priority
A3: 1 | B3: 1 | D3: 33 | E3: Male | F3: Outdoor | G3: Desk-job | H3: 8 | I3: 4 | J3: Blurred distance | K3: Night driving difficulty, Double vision, Watering | L3: FALSE | M3: None | N3: 0 | O3: Not applicable | Q3: 12 | R3: FALSE | S3: FALSE | T3: FALSE | U3: FALSE | V3: FALSE | W3: FALSE | X3: None | Y3: FALSE | Z3: FALSE | AA3: FALSE | AB3: Sharpest vision | AC3: Aim 6/6 if possible | AD3: High
A4: 2 | B4: 2 | C4: 222 | D4: 65 | E4: Female | F4: Indoor | G4: Desk-job | H4: 8 | I4: 2 | J4: Routine check | L4: FALSE | M4: None | O4: Not applicable | R4: FALSE | S4: FALSE | T4: FALSE | U4: FALSE | V4: FALSE | W4: FALSE | X4: None | Y4: FALSE | Z4: FALSE | AA4: FALSE | AB4: Sharpest vision | AC4: Aim 6/6 if possible | AD4: High
A5: 3 | B5: 3 | C5: 3232 | D5: 35 | E5: Male | F5: Hybrid | G5: Desk-job | H5: 12 | I5: 2 | J5: Headache | L5: TRUE | M5: Single Vision | N5: 12 | O5: Satisfied | Q5: 12 | R5: TRUE | S5: FALSE | T5: FALSE | U5: FALSE | V5: FALSE | W5: FALSE | X5: None | Y5: FALSE | Z5: FALSE | AA5: FALSE | AB5: Comfort-first | AC5: Aim 6/6 if possible | AD5: Low
A6: 4 | B6: 4 | C6: 09.03.2026 | D6: 22 | E6: Male | F6: Hybrid | G6: Student | H6: 10 | I6: 0 | J6: Blurred distance | L6: TRUE | M6: Single Vision | N6: 4 | O6: Satisfied | Q6: 4 | R6: TRUE | S6: FALSE | T6: FALSE | U6: FALSE | V6: FALSE | W6: FALSE | X6: None | Y6: FALSE | Z6: FALSE | AA6: FALSE | AB6: Balanced | AC6: Aim 6/6 if possible | AD6: High
A7: 5 | B7: 5 | C7: 09.03.2026 | D7: 23 | E7: Female | F7: Indoor | G7: Desk-job | H7: 12 | I7: 0 | J7: Headache | K7: Watering | L7: TRUE | M7: Single Vision | N7: 18 | O7: Not satisfied | P7: Headache | Q7: 6 | R7: TRUE | S7: FALSE | T7: TRUE | U7: FALSE | V7: TRUE | W7: FALSE | X7: None | Y7: FALSE | Z7: FALSE | AA7: FALSE | AB7: Comfort-first | AC7: Aim 6/6 if possible | AD7: Low
A8: 6 | B8: 6 | C8: 09.03.2026 | D8: 45 | E8: Male | F8: Indoor | G8: Desk-job | H8: 8 | I8: 0 | J8: Routine check | L8: TRUE | M8: Progressive | N8: 12 | O8: Satisfied | Q8: 12 | R8: FALSE | T8: FALSE | U8: FALSE | V8: FALSE | W8: FALSE | X8: None | Y8: FALSE | Z8: FALSE | AA8: FALSE | AB8: Comfort-first | AC8: Aim 6/6 if possible | AD8: High

Sheet Derived_Variables
A1: visit_id | B1: dv_age_bucket | C1: dv_distance_priority | D1: dv_near_priority | E1: dv_symptom_risk_level | F1: dv_medical_risk_level | G1: dv_stability_level | H1: dv_ar_lenso_mismatch_level_RE | I1: dv_ar_lenso_mismatch_level_LE | J1: dv_start_source_policy | K1: dv_start_rx_RE_sph | L1: dv_start_rx_RE_cyl | M1: dv_start_rx_RE_axis | N1: dv_start_rx_LE_sph | O1: dv_start_rx_LE_cyl | P1: dv_start_rx_LE_axis | Q1: dv_add_expected | R1: dv_target_distance_va | S1: dv_endpoint_bias_policy | T1: dv_step_size_policy | U1: dv_max_delta_from_start_sph | V1: dv_max_delta_from_ar_sph | W1: dv_axis_tolerance_deg | X1: dv_cyl_tolerance_D | Y1: dv_requires_optom_review | Z1: dv_anomaly_watch | AA1: dv_expected_convergence_time | AB1: dv_branching_guardrails | AC1: dv_confidence_requirement | AD1: dv_fogging_policy | AE1: dv_fogging_amount_D | AF1: dv_fogging_clearance_mode | AG1: dv_fogging_required_confirmation | AH1: dv_axis_step_policy | AI1: dv_duochrome_max_flips | AJ1: dv_near_test_required
A2: 1 | B2: {=LET(age,XLOOKUP($A2,Patient_Input_Data!$B:$B,Patient_Input_Data!$D:$D,""),childMax,XLOOKUP("age_child_max",Calibration!$B:$B,Calibration!$C:$C),presMin,XLOOKUP("age_presbyope_min",Calibration!$B:$B,Calibration!$C:$C),IF(age<childMax,"Child",IF(age>=presMin,"Presbyope","Adult")))} -> Adult | C2: {=LET(drive,XLOOKUP($A2,Patient_Input_Data!$B:$B,Patient_Input_Data!$I:$I,""),occ,XLOOKUP($A2,Patient_Input_Data!$B:$B,Patient_Input_Data!$G:$G,""),pri,XLOOKUP($A2,Patient_Input_Data!$B:$B,Patient_Input_Data!$AB:$AB,""),driveHigh,XLOOKUP("driving_hours_high",Calibration!$B:$B,Calibration!$C:$C),base,IF(OR(drive>=driveHigh,occ="Driver"),"High","Medium"),IF(pri="Comfort-first",IF(base="High","Medium","Low"),base))} -> High | D2: {=LET(np,XLOOKUP($A2,Patient_Input_Data!$B:$B,Patient_Input_Data!$AD:$AD,""),st,XLOOKUP($A2,Patient_Input_Data!$B:$B,Patient_Input_Data!$H:$H,""),rs,XLOOKUP($A2,Patient_Input_Data!$B:$B,Patient_Input_Data!$J:$J,""),screenHigh,XLOOKUP("screen_time_high",Calibration!$B:$B,Calibration!$C:$C),IF(np<>"",np,IF(OR(st>=screenHigh,rs="Blurred near"),"High","Medium")))} -> High | E2: =IFERROR(__xludf.DUMMYFUNCTION("LET(s,XLOOKUP($A2,Patient_Input_Data!$B:$B,Patient_Input_Data!$K:$K,""""),IF(OR(REGEXMATCH(s,""Sudden vision change""),REGEXMATCH(s,""Double vision"")),""High"",IF(OR(REGEXMATCH(s,""Glare/halos""),REGEXMATCH(s,""Night driving difficulty""),REGEXMATCH(s,"""&"Fluctuating vision"")),""Moderate"",""None"")))"),"High") -> High | F2: {=LET(di,(XLOOKUP($A2,Patient_Input_Data!$B:$B,Patient_Input_Data!$U:$U,"")="True"),surg,XLOOKUP($A2,Patient_Input_Data!$B:$B,Patient_Input_Data!$X:$X,"")<>"None",ker,(XLOOKUP($A2,Patient_Input_Data!$B:$B,Patient_Input_Data!$Y:$Y,"")="True"),amb,(XLOOKUP($A2,Patient_Input_Data!$B:$B,Patient_Input_Data!$Z:$Z,"")="True"),inf,(XLOOKUP($A2,Patient_Input_Data!$B:$B,Patient_Input_Data!$AA:$AA,"")="True"),IF(OR(ker,inf),"High",IF(OR(di,surg,amb),"Moderate","None")))} -> None | G2: {=LET(last,XLOOKUP($A2,Patient_Input_Data!$B:$B,Patient_Input_Data!$Q:$Q,""),fl,(XLOOKUP($A2,Patient_Input_Data!$B:$B,Patient_Input_Data!$T:$T,"")="True"),chg,(XLOOKUP($A2,Patient_Input_Data!$B:$B,Patient_Input_Data!$S:$S,"")="True"),di,(XLOOKUP($A2,Patient_Input_Data!$B:$B,Patient_Input_Data!$U:$U,"")="True"),uncertainMonths,XLOOKUP("last_eye_test_uncertain_months",Calibration!$B:$B,Calibration!$C:$C),IF(OR(fl,chg),"Unstable",IF(OR(di,last>uncertainMonths),"Uncertain","Stable")))} -> Stable | H2: {=LET( arS,XLOOKUP($A2,AR_Input!$A:$A,AR_Input!$B:$B,""), arC,XLOOKUP($A2,AR_Input!$A:$A,AR_Input!$C:$C,""), arA,XLOOKUP($A2,AR_Input!$A:$A,AR_Input!$D:$D,""), lnS,XLOOKUP($A2,Lenso_Input!$A:$A,Lenso_Input!$B:$B,""), lnC,XLOOKUP($A2,Lenso_Input!$A:$A,Lenso_Input!$C:$C,""), lnA,XLOOKUP($A2,Lenso_Input!$A:$A,Lenso_Input!$D:$D,""), hasAR,AND(arS<>"",arC<>"",arA<>""), hasLenso,AND(lnS<>"",lnC<>"",lnA<>""), sMed,XLOOKUP("mismatch_re_sph_medium",Calibration!$B:$B,Calibration!$C:$C), sLarge,XLOOKUP("mismatch_re_sph_large",Calibration!$B:$B,Calibration!$C:$C), cMed,XLOOKUP("mismatch_re_cyl_medium",Calibration!$B:$B,Calibration!$C:$C), cLarge,XLOOKUP("mismatch_re_cyl_large",Calibration!$B:$B,Calibration!$C:$C), aMed,XLOOKUP("mismatch_re_axis_medium",Calibration!$B:$B,Calibration!$C:$C), aLarge,XLOOKUP("mismatch_re_axis_large",Calibration!$B:$B,Calibration!$C:$C), IF( NOT(AND(hasAR,hasLenso)), "Small", LET( dS,ABS(VALUE(arS)-VALUE(lnS)), dC,ABS(VALUE(arC)-VALUE(lnC)), dA,MIN(ABS(VALUE(arA)-VALUE(lnA)),180-ABS(VALUE(arA)-VALUE(lnA))), IF(OR(dS>sLarge,dC>cLarge,dA>aLarge),"Large",IF(OR(dS>sMed,dC>cMed,dA>aMed),"Medium","Small")) ) ))} -> Medium | I2: {=LET( arS,XLOOKUP($A2,AR_Input!$A:$A,AR_Input!$E:$E,""), arC,XLOOKUP($A2,AR_Input!$A:$A,AR_Input!$F:$F,""), arA,XLOOKUP($A2,AR_Input!$A:$A,AR_Input!$G:$G,""), lnS,XLOOKUP($A2,Lenso_Input!$A:$A,Lenso_Input!$F:$F,""), lnC,XLOOKUP($A2,Lenso_Input!$A:$A,Lenso_Input!$G:$G,""), lnA,XLOOKUP($A2,Lenso_Input!$A:$A,Lenso_Input!$H:$H,""), hasAR,AND(arS<>"",arC<>"",arA<>""), hasLenso,AND(lnS<>"",lnC<>"",lnA<>""), sMed,XLOOKUP("mismatch_le_sph_medium",Calibration!$B:$B,Calibration!$C:$C), sLarge,XLOOKUP("mismatch_le_sph_large",Calibration!$B:$B,Calibration!$C:$C), cMed,XLOOKUP("mismatch_le_cyl_medium",Calibration!$B:$B,Calibration!$C:$C), cLarge,XLOOKUP("mismatch_le_cyl_large",Calibration!$B:$B,Calibration!$C:$C), aMed,XLOOKUP("mismatch_le_axis_medium",Calibration!$B:$B,Calibration!$C:$C), aLarge,XLOOKUP("mismatch_le_axis_large",Calibration!$B:$B,Calibration!$C:$C), IF( NOT(AND(hasAR,hasLenso)), "Small", LET( dS,ABS(VALUE(arS)-VALUE(lnS)), dC,ABS(VALUE(arC)-VALUE(lnC)), dA,MIN(ABS(VALUE(arA)-VALUE(lnA)),180-ABS(VALUE(arA)-VALUE(lnA))), IF(OR(dS>sLarge,dC>cLarge,dA>aLarge),"Large",IF(OR(dS>sMed,dC>cMed,dA>aMed),"Medium","Small")) ) ))} -> Large | J2: {=LET(sat,XLOOKUP($A2,Patient_Input_Data!$B:$B,Patient_Input_Data!$O:$O,""),rs,XLOOKUP($A2,Patient_Input_Data!$B:$B,Patient_Input_Data!$J:$J,""),stab,$G2,misR,$H2,misL,$I2,startAR,XLOOKUP("start_policy_if_only_ar",Calibration!$B:$B,Calibration!$C:$C),startL,XLOOKUP("start_policy_if_only_lenso",Calibration!$B:$B,Calibration!$C:$C),startSat,XLOOKUP("start_policy_if_satisfied_small_mismatch",Calibration!$B:$B,Calibration!$C:$C),startUnsat,XLOOKUP("start_policy_if_unsatisfied_or_blur",Calibration!$B:$B,Calibration!$C:$C),startHybrid,XLOOKUP("start_policy_if_large_mismatch_or_unstable",Calibration!$B:$B,Calibration!$C:$C),arR,XLOOKUP($A2,AR_Input!$A:$A,AR_Input!$B:$B,""),arL,XLOOKUP($A2,AR_Input!$A:$A,AR_Input!$E:$E,""),lenR,XLOOKUP($A2,Lenso_Input!$A:$A,Lenso_Input!$B:$B,""),lenL,XLOOKUP($A2,Lenso_Input!$A:$A,Lenso_Input!$F:$F,""),hasAR,OR(arR<>"",arL<>""),hasLenso,OR(lenR<>"",lenL<>""),IF(AND(hasAR,NOT(hasLenso)),startAR,IF(AND(hasLenso,NOT(hasAR)),startL,IF(AND(sat="Satisfied",misR="Small",misL="Small"),startSat,IF(OR(sat="Not satisfied",rs="Blurred distance",rs="Blurred near"),startUnsat,IF(OR(misR="Large",misL="Large",stab="Unstable"),startHybrid,startAR))))))} -> Start_AR | K2: {=LET(ar,XLOOKUP($A2,AR_Input!$A:$A,AR_Input!$B:$B,""),ln,XLOOKUP($A2,Lenso_Input!$A:$A,Lenso_Input!$B:$B,""),pol,$J2,step,XLOOKUP("hybrid_rounding_step",Calibration!$B:$B,Calibration!$C:$C),IF(pol="Start_AR",ar,IF(pol="Start_Lenso",IF(ln<>"",ln,ar),IF(AND(ar<>"",ln<>""),ROUND(((ar+ln)/2)/step,0)*step,IF(ar<>"",ar,ln)))))} -> -2.5 | L2: {=LET(ar,XLOOKUP($A2,AR_Input!$A:$A,AR_Input!$C:$C,""),ln,XLOOKUP($A2,Lenso_Input!$A:$A,Lenso_Input!$C:$C,""),pol,$J2,step,XLOOKUP("hybrid_rounding_step",Calibration!$B:$B,Calibration!$C:$C),IF(pol="Start_AR",ar,IF(pol="Start_Lenso",IF(ln<>"",ln,ar),IF(AND(ar<>"",ln<>""),ROUND(((ar+ln)/2)/step,0)*step,IF(ar<>"",ar,ln)))))} -> -1.75 | M2: {=LET(ar,XLOOKUP($A2,AR_Input!$A:$A,AR_Input!$D:$D,""),ln,XLOOKUP($A2,Lenso_Input!$A:$A,Lenso_Input!$D:$D,""),pol,$J2,IF(pol="Start_AR",ar,IF(pol="Start_Lenso",IF(ln<>"",ln,ar),IF(ar<>"",ar,ln))))} -> 90 | N2: {=LET(ar,XLOOKUP($A2,AR_Input!$A:$A,AR_Input!$E:$E,""),ln,XLOOKUP($A2,Lenso_Input!$A:$A,Lenso_Input!$F:$F,""),pol,$J2,step,XLOOKUP("hybrid_rounding_step",Calibration!$B:$B,Calibration!$C:$C),IF(pol="Start_AR",ar,IF(pol="Start_Lenso",IF(ln<>"",ln,ar),IF(AND(ar<>"",ln<>""),ROUND(((ar+ln)/2)/step,0)*step,IF(ar<>"",ar,ln)))))} -> -2.5 | O2: {=LET(ar,XLOOKUP($A2,AR_Input!$A:$A,AR_Input!$F:$F,""),ln,XLOOKUP($A2,Lenso_Input!$A:$A,Lenso_Input!$G:$G,""),pol,$J2,step,XLOOKUP("hybrid_rounding_step",Calibration!$B:$B,Calibration!$C:$C),IF(pol="Start_AR",ar,IF(pol="Start_Lenso",IF(ln<>"",ln,ar),IF(AND(ar<>"",ln<>""),ROUND(((ar+ln)/2)/step,0)*step,IF(ar<>"",ar,ln)))))} -> -3.75 | P2: {=LET(ar,XLOOKUP($A2,AR_Input!$A:$A,AR_Input!$G:$G,""),ln,XLOOKUP($A2,Lenso_Input!$A:$A,Lenso_Input!$H:$H,""),pol,$J2,IF(pol="Start_AR",ar,IF(pol="Start_Lenso",IF(ln<>"",ln,ar),IF(ar<>"",ar,ln))))} -> 70 | Q2: {=LET(a,XLOOKUP($A2,Patient_Input_Data!$B:$B,Patient_Input_Data!$D:$D,""),wt,XLOOKUP($A2,Patient_Input_Data!$B:$B,Patient_Input_Data!$M:$M,""),addR,XLOOKUP($A2,Lenso_Input!$A:$A,Lenso_Input!$E:$E,""),addL,XLOOKUP($A2,Lenso_Input!$A:$A,Lenso_Input!$I:$I,""),near,D2,likelyAge,XLOOKUP("add_likely_min_age",Calibration!$B:$B,Calibration!$C:$C),possibleAge,XLOOKUP("add_possible_min_age",Calibration!$B:$B,Calibration!$C:$C),IF(OR(a>=likelyAge,wt="Progressive",wt="Bifocal",addR<>"",addL<>""),"Likely",IF(AND(a>=possibleAge,a<=likelyAge-1,near="High"),"Possible","None")))} -> Likely | R2: {=LET(dt,XLOOKUP($A2,Patient_Input_Data!$B:$B,Patient_Input_Data!$AC:$AC,""),sym,E2,med,F2,stab,G2,target66,XLOOKUP("default_distance_target",Calibration!$B:$B,Calibration!$C:$C),target69,XLOOKUP("high_risk_distance_target",Calibration!$B:$B,Calibration!$C:$C),IF(dt<>"",IF(OR(dt="Accept 6/9 if needed",dt="6/9 acceptable",dt="6/9_acceptable"),target69,target66),IF(OR(sym="High",med="High",stab="Unstable"),target69,target66)))} -> 6/6_target | S2: =IFERROR(__xludf.DUMMYFUNCTION("LET(pri,XLOOKUP($A2,Patient_Input_Data!$B:$B,Patient_Input_Data!$AB:$AB,""""),ageB,B2,near,D2,oc,XLOOKUP($A2,Patient_Input_Data!$B:$B,Patient_Input_Data!$G:$G,""""),sym,E2,s,XLOOKUP($A2,Patient_Input_Data!$B:$B,Patient_Input_Data!$K:$K,""""),IF(sym=""High"&""",""Neutral"",IF(AND(pri=""Comfort-first"",ageB=""Presbyope"",near=""High""),""Undercorrect"",IF(AND(oc=""Driver"",OR(REGEXMATCH(s,""Night driving difficulty""),REGEXMATCH(s,""Glare/halos""))),""Overcorrect"",""Neutral""))))"),"Neutral") -> Neutral | T2: =LET(stab,G2,med,F2,sym,E2,IF(OR(stab="Unstable",med="High",sym="High"),"Conservative",IF(AND(stab="Stable",med="None",sym="None"),"Aggressive","Standard"))) -> Conservative | U2: {=IF(T2="Conservative",XLOOKUP("max_delta_start_conservative",Calibration!B:B,Calibration!C:C),IF(T2="Standard",XLOOKUP("max_delta_start_standard",Calibration!B:B,Calibration!C:C),XLOOKUP("max_delta_start_aggressive",Calibration!B:B,Calibration!C:C)))} -> 1.25 | V2: {=XLOOKUP("max_delta_ar_standard",Calibration!B:B,Calibration!C:C)} -> 3 | W2: {=IF(AB2="Strict", XLOOKUP("axis_tol_strict",Calibration!$B:$B,Calibration!$C:$C), IF(AB2="Normal", XLOOKUP("axis_tol_normal",Calibration!$B:$B,Calibration!$C:$C), XLOOKUP("axis_tol_relaxed",Calibration!$B:$B,Calibration!$C:$C)))} -> 1 | X2: {=IF(T2="Aggressive", XLOOKUP("cyl_tol_aggressive",Calibration!$B:$B,Calibration!$C:$C), XLOOKUP("cyl_tol_standard",Calibration!$B:$B,Calibration!$C:$C))} -> 0.25 | Y2: {=IF(OR(E2="High",F2="High",XLOOKUP($A2,Patient_Input_Data!$B:$B,Patient_Input_Data!$AA:$AA,"")="True"),TRUE,FALSE)} -> TRUE | Z2: =IF(OR(G2<>"Stable",J2="Hybrid",H2="Large",I2="Large"),TRUE,FALSE) -> TRUE | AA2: =IF(AND(B2="Adult",G2="Stable",E2="None",F2="None"),"Fast",IF(OR(B2="Presbyope",G2<>"Stable",E2="High",F2="High"),"Slow","Normal")) -> Slow | AB2: =IF(OR(E2="High",F2="High",G2="Unstable"),"Strict",IF(OR(E2="Moderate",F2="Moderate",G2="Uncertain"),"Normal","Relaxed")) -> Strict | AC2: =IF(OR(G2<>"Stable",E2="High",F2="High"),"High",IF(OR(E2="Moderate",F2="Moderate"),"Medium","Low")) -> High | AD2: =IF(OR(B2="Presbyope",G2="Unstable",F2="High",E2="High"),"Strong_Fog",IF(AND(B2="Adult",G2="Stable",OR(F2="Moderate",E2="Moderate")),"Standard_Fog","No_Fog")) -> Strong_Fog | AE2: {=IF(AD2="Strong_Fog",XLOOKUP("strong_fog_amount",Calibration!B:B,Calibration!C:C),IF(AD2="Standard_Fog",XLOOKUP("standard_fog_amount",Calibration!B:B,Calibration!C:C),XLOOKUP("no_fog_amount",Calibration!B:B,Calibration!C:C)))} -> 1 | AF2: =IF(AND(AD2="Strong_Fog",R2="6/9_acceptable"),"Early_Stop_if_Risk",IF(AD2="Strong_Fog","StepDown_0.25","StepDown_0.50_then_0.25")) -> StepDown_0.25 | AG2: =IF(OR(G2="Unstable",E2="High"),"High",IF(OR(E2="Moderate",F2="Moderate"),"Medium","Low")) -> High | AH2: =IF(OR(E2="High",F2="High",G2="Unstable"),"Fine","Normal") -> Fine | AI2: {=IF(AB2="Strict", XLOOKUP("duochrome_max_flips_strict",Calibration!$B:$B,Calibration!$C:$C), IF(AB2="Normal", XLOOKUP("duochrome_max_flips_normal",Calibration!$B:$B,Calibration!$C:$C), XLOOKUP("duochrome_max_flips_relaxed",Calibration!$B:$B,Calibration!$C:$C)))} -> 3 | AJ2: {=LET( nearPr,D2, addExp,Q2, ageB,B2, forceHighNear,XLOOKUP("allow_high_near_priority_to_force_near",Calibration!$B:$B,Calibration!$C:$C), allowPossible,XLOOKUP("trigger_near_if_dv_add_expected_possible",Calibration!$B:$B,Calibration!$C:$C), allowLikely,XLOOKUP("trigger_near_if_dv_add_expected_likely",Calibration!$B:$B,Calibration!$C:$C), IF( OR( AND(addExp="Likely",allowLikely=TRUE), AND(addExp="Possible",allowPossible=TRUE), AND(nearPr="High",forceHighNear=TRUE) ), TRUE, FALSE ))} -> TRUE
A3: 2 | B3: {=LET(age,XLOOKUP($A3,Patient_Input_Data!$B:$B,Patient_Input_Data!$D:$D,""),childMax,XLOOKUP("age_child_max",Calibration!$B:$B,Calibration!$C:$C),presMin,XLOOKUP("age_presbyope_min",Calibration!$B:$B,Calibration!$C:$C),IF(age<childMax,"Child",IF(age>=presMin,"Presbyope","Adult")))} -> Presbyope | C3: {=LET(drive,XLOOKUP($A3,Patient_Input_Data!$B:$B,Patient_Input_Data!$I:$I,""),occ,XLOOKUP($A3,Patient_Input_Data!$B:$B,Patient_Input_Data!$G:$G,""),pri,XLOOKUP($A3,Patient_Input_Data!$B:$B,Patient_Input_Data!$AB:$AB,""),driveHigh,XLOOKUP("driving_hours_high",Calibration!$B:$B,Calibration!$C:$C),base,IF(OR(drive>=driveHigh,occ="Driver"),"High","Medium"),IF(pri="Comfort-first",IF(base="High","Medium","Low"),base))} -> High | D3: {=LET(np,XLOOKUP($A3,Patient_Input_Data!$B:$B,Patient_Input_Data!$AD:$AD,""),st,XLOOKUP($A3,Patient_Input_Data!$B:$B,Patient_Input_Data!$H:$H,""),rs,XLOOKUP($A3,Patient_Input_Data!$B:$B,Patient_Input_Data!$J:$J,""),screenHigh,XLOOKUP("screen_time_high",Calibration!$B:$B,Calibration!$C:$C),IF(np<>"",np,IF(OR(st>=screenHigh,rs="Blurred near"),"High","Medium")))} -> High | E3: =IFERROR(__xludf.DUMMYFUNCTION("LET(s,XLOOKUP($A3,Patient_Input_Data!$B:$B,Patient_Input_Data!$K:$K,""""),IF(OR(REGEXMATCH(s,""Sudden vision change""),REGEXMATCH(s,""Double vision"")),""High"",IF(OR(REGEXMATCH(s,""Glare/halos""),REGEXMATCH(s,""Night driving difficulty""),REGEXMATCH(s,"""&"Fluctuating vision"")),""Moderate"",""None"")))"),"None") -> None | F3: {=LET(di,(XLOOKUP($A3,Patient_Input_Data!$B:$B,Patient_Input_Data!$U:$U,"")="True"),surg,XLOOKUP($A3,Patient_Input_Data!$B:$B,Patient_Input_Data!$X:$X,"")<>"None",ker,(XLOOKUP($A3,Patient_Input_Data!$B:$B,Patient_Input_Data!$Y:$Y,"")="True"),amb,(XLOOKUP($A3,Patient_Input_Data!$B:$B,Patient_Input_Data!$Z:$Z,"")="True"),inf,(XLOOKUP($A3,Patient_Input_Data!$B:$B,Patient_Input_Data!$AA:$AA,"")="True"),IF(OR(ker,inf),"High",IF(OR(di,surg,amb),"Moderate","None")))} -> None | G3: {=LET(last,XLOOKUP($A3,Patient_Input_Data!$B:$B,Patient_Input_Data!$Q:$Q,""),fl,(XLOOKUP($A3,Patient_Input_Data!$B:$B,Patient_Input_Data!$T:$T,"")="True"),chg,(XLOOKUP($A3,Patient_Input_Data!$B:$B,Patient_Input_Data!$S:$S,"")="True"),di,(XLOOKUP($A3,Patient_Input_Data!$B:$B,Patient_Input_Data!$U:$U,"")="True"),uncertainMonths,XLOOKUP("last_eye_test_uncertain_months",Calibration!$B:$B,Calibration!$C:$C),IF(OR(fl,chg),"Unstable",IF(OR(di,last>uncertainMonths),"Uncertain","Stable")))} -> Stable | H3: {=LET( arS,XLOOKUP($A3,AR_Input!$A:$A,AR_Input!$B:$B,""), arC,XLOOKUP($A3,AR_Input!$A:$A,AR_Input!$C:$C,""), arA,XLOOKUP($A3,AR_Input!$A:$A,AR_Input!$D:$D,""), lnS,XLOOKUP($A3,Lenso_Input!$A:$A,Lenso_Input!$B:$B,""), lnC,XLOOKUP($A3,Lenso_Input!$A:$A,Lenso_Input!$C:$C,""), lnA,XLOOKUP($A3,Lenso_Input!$A:$A,Lenso_Input!$D:$D,""), hasAR,AND(arS<>"",arC<>"",arA<>""), hasLenso,AND(lnS<>"",lnC<>"",lnA<>""), sMed,XLOOKUP("mismatch_re_sph_medium",Calibration!$B:$B,Calibration!$C:$C), sLarge,XLOOKUP("mismatch_re_sph_large",Calibration!$B:$B,Calibration!$C:$C), cMed,XLOOKUP("mismatch_re_cyl_medium",Calibration!$B:$B,Calibration!$C:$C), cLarge,XLOOKUP("mismatch_re_cyl_large",Calibration!$B:$B,Calibration!$C:$C), aMed,XLOOKUP("mismatch_re_axis_medium",Calibration!$B:$B,Calibration!$C:$C), aLarge,XLOOKUP("mismatch_re_axis_large",Calibration!$B:$B,Calibration!$C:$C), IF( NOT(AND(hasAR,hasLenso)), "Small", LET( dS,ABS(VALUE(arS)-VALUE(lnS)), dC,ABS(VALUE(arC)-VALUE(lnC)), dA,MIN(ABS(VALUE(arA)-VALUE(lnA)),180-ABS(VALUE(arA)-VALUE(lnA))), IF(OR(dS>sLarge,dC>cLarge,dA>aLarge),"Large",IF(OR(dS>sMed,dC>cMed,dA>aMed),"Medium","Small")) ) ))} -> Small | I3: {=LET( arS,XLOOKUP($A3,AR_Input!$A:$A,AR_Input!$E:$E,""), arC,XLOOKUP($A3,AR_Input!$A:$A,AR_Input!$F:$F,""), arA,XLOOKUP($A3,AR_Input!$A:$A,AR_Input!$G:$G,""), lnS,XLOOKUP($A3,Lenso_Input!$A:$A,Lenso_Input!$F:$F,""), lnC,XLOOKUP($A3,Lenso_Input!$A:$A,Lenso_Input!$G:$G,""), lnA,XLOOKUP($A3,Lenso_Input!$A:$A,Lenso_Input!$H:$H,""), hasAR,AND(arS<>"",arC<>"",arA<>""), hasLenso,AND(lnS<>"",lnC<>"",lnA<>""), sMed,XLOOKUP("mismatch_le_sph_medium",Calibration!$B:$B,Calibration!$C:$C), sLarge,XLOOKUP("mismatch_le_sph_large",Calibration!$B:$B,Calibration!$C:$C), cMed,XLOOKUP("mismatch_le_cyl_medium",Calibration!$B:$B,Calibration!$C:$C), cLarge,XLOOKUP("mismatch_le_cyl_large",Calibration!$B:$B,Calibration!$C:$C), aMed,XLOOKUP("mismatch_le_axis_medium",Calibration!$B:$B,Calibration!$C:$C), aLarge,XLOOKUP("mismatch_le_axis_large",Calibration!$B:$B,Calibration!$C:$C), IF( NOT(AND(hasAR,hasLenso)), "Small", LET( dS,ABS(VALUE(arS)-VALUE(lnS)), dC,ABS(VALUE(arC)-VALUE(lnC)), dA,MIN(ABS(VALUE(arA)-VALUE(lnA)),180-ABS(VALUE(arA)-VALUE(lnA))), IF(OR(dS>sLarge,dC>cLarge,dA>aLarge),"Large",IF(OR(dS>sMed,dC>cMed,dA>aMed),"Medium","Small")) ) ))} -> Small | J3: {=LET(sat,XLOOKUP($A3,Patient_Input_Data!$B:$B,Patient_Input_Data!$O:$O,""),rs,XLOOKUP($A3,Patient_Input_Data!$B:$B,Patient_Input_Data!$J:$J,""),stab,$G3,misR,$H3,misL,$I3,startAR,XLOOKUP("start_policy_if_only_ar",Calibration!$B:$B,Calibration!$C:$C),startL,XLOOKUP("start_policy_if_only_lenso",Calibration!$B:$B,Calibration!$C:$C),startSat,XLOOKUP("start_policy_if_satisfied_small_mismatch",Calibration!$B:$B,Calibration!$C:$C),startUnsat,XLOOKUP("start_policy_if_unsatisfied_or_blur",Calibration!$B:$B,Calibration!$C:$C),startHybrid,XLOOKUP("start_policy_if_large_mismatch_or_unstable",Calibration!$B:$B,Calibration!$C:$C),arR,XLOOKUP($A3,AR_Input!$A:$A,AR_Input!$B:$B,""),arL,XLOOKUP($A3,AR_Input!$A:$A,AR_Input!$E:$E,""),lenR,XLOOKUP($A3,Lenso_Input!$A:$A,Lenso_Input!$B:$B,""),lenL,XLOOKUP($A3,Lenso_Input!$A:$A,Lenso_Input!$F:$F,""),hasAR,OR(arR<>"",arL<>""),hasLenso,OR(lenR<>"",lenL<>""),IF(AND(hasAR,NOT(hasLenso)),startAR,IF(AND(hasLenso,NOT(hasAR)),startL,IF(AND(sat="Satisfied",misR="Small",misL="Small"),startSat,IF(OR(sat="Not satisfied",rs="Blurred distance",rs="Blurred near"),startUnsat,IF(OR(misR="Large",misL="Large",stab="Unstable"),startHybrid,startAR))))))} -> Start_AR | K3: {=LET(ar,XLOOKUP($A3,AR_Input!$A:$A,AR_Input!$B:$B,""),ln,XLOOKUP($A3,Lenso_Input!$A:$A,Lenso_Input!$B:$B,""),pol,$J3,step,XLOOKUP("hybrid_rounding_step",Calibration!$B:$B,Calibration!$C:$C),IF(pol="Start_AR",ar,IF(pol="Start_Lenso",IF(ln<>"",ln,ar),IF(AND(ar<>"",ln<>""),ROUND(((ar+ln)/2)/step,0)*step,IF(ar<>"",ar,ln)))))} -> -0.5 | L3: {=LET(ar,XLOOKUP($A3,AR_Input!$A:$A,AR_Input!$C:$C,""),ln,XLOOKUP($A3,Lenso_Input!$A:$A,Lenso_Input!$C:$C,""),pol,$J3,step,XLOOKUP("hybrid_rounding_step",Calibration!$B:$B,Calibration!$C:$C),IF(pol="Start_AR",ar,IF(pol="Start_Lenso",IF(ln<>"",ln,ar),IF(AND(ar<>"",ln<>""),ROUND(((ar+ln)/2)/step,0)*step,IF(ar<>"",ar,ln)))))} -> -0.75 | M3: {=LET(ar,XLOOKUP($A3,AR_Input!$A:$A,AR_Input!$D:$D,""),ln,XLOOKUP($A3,Lenso_Input!$A:$A,Lenso_Input!$D:$D,""),pol,$J3,IF(pol="Start_AR",ar,IF(pol="Start_Lenso",IF(ln<>"",ln,ar),IF(ar<>"",ar,ln))))} -> 50 | N3: {=LET(ar,XLOOKUP($A3,AR_Input!$A:$A,AR_Input!$E:$E,""),ln,XLOOKUP($A3,Lenso_Input!$A:$A,Lenso_Input!$F:$F,""),pol,$J3,step,XLOOKUP("hybrid_rounding_step",Calibration!$B:$B,Calibration!$C:$C),IF(pol="Start_AR",ar,IF(pol="Start_Lenso",IF(ln<>"",ln,ar),IF(AND(ar<>"",ln<>""),ROUND(((ar+ln)/2)/step,0)*step,IF(ar<>"",ar,ln)))))} -> -0.25 | O3: {=LET(ar,XLOOKUP($A3,AR_Input!$A:$A,AR_Input!$F:$F,""),ln,XLOOKUP($A3,Lenso_Input!$A:$A,Lenso_Input!$G:$G,""),pol,$J3,step,XLOOKUP("hybrid_rounding_step",Calibration!$B:$B,Calibration!$C:$C),IF(pol="Start_AR",ar,IF(pol="Start_Lenso",IF(ln<>"",ln,ar),IF(AND(ar<>"",ln<>""),ROUND(((ar+ln)/2)/step,0)*step,IF(ar<>"",ar,ln)))))} -> -1 | P3: {=LET(ar,XLOOKUP($A3,AR_Input!$A:$A,AR_Input!$G:$G,""),ln,XLOOKUP($A3,Lenso_Input!$A:$A,Lenso_Input!$H:$H,""),pol,$J3,IF(pol="Start_AR",ar,IF(pol="Start_Lenso",IF(ln<>"",ln,ar),IF(ar<>"",ar,ln))))} -> 60 | Q3: {=LET(a,XLOOKUP($A3,Patient_Input_Data!$B:$B,Patient_Input_Data!$D:$D,""),wt,XLOOKUP($A3,Patient_Input_Data!$B:$B,Patient_Input_Data!$M:$M,""),addR,XLOOKUP($A3,Lenso_Input!$A:$A,Lenso_Input!$E:$E,""),addL,XLOOKUP($A3,Lenso_Input!$A:$A,Lenso_Input!$I:$I,""),near,D3,likelyAge,XLOOKUP("add_likely_min_age",Calibration!$B:$B,Calibration!$C:$C),possibleAge,XLOOKUP("add_possible_min_age",Calibration!$B:$B,Calibration!$C:$C),IF(OR(a>=likelyAge,wt="Progressive",wt="Bifocal",addR<>"",addL<>""),"Likely",IF(AND(a>=possibleAge,a<=likelyAge-1,near="High"),"Possible","None")))} -> Likely | R3: {=LET(dt,XLOOKUP($A3,Patient_Input_Data!$B:$B,Patient_Input_Data!$AC:$AC,""),sym,E3,med,F3,stab,G3,target66,XLOOKUP("default_distance_target",Calibration!$B:$B,Calibration!$C:$C),target69,XLOOKUP("high_risk_distance_target",Calibration!$B:$B,Calibration!$C:$C),IF(dt<>"",IF(OR(dt="Accept 6/9 if needed",dt="6/9 acceptable",dt="6/9_acceptable"),target69,target66),IF(OR(sym="High",med="High",stab="Unstable"),target69,target66)))} -> 6/6_target | S3: =IFERROR(__xludf.DUMMYFUNCTION("LET(pri,XLOOKUP($A3,Patient_Input_Data!$B:$B,Patient_Input_Data!$AB:$AB,""""),ageB,B3,near,D3,oc,XLOOKUP($A3,Patient_Input_Data!$B:$B,Patient_Input_Data!$G:$G,""""),sym,E3,s,XLOOKUP($A3,Patient_Input_Data!$B:$B,Patient_Input_Data!$K:$K,""""),IF(sym=""High"&""",""Neutral"",IF(AND(pri=""Comfort-first"",ageB=""Presbyope"",near=""High""),""Undercorrect"",IF(AND(oc=""Driver"",OR(REGEXMATCH(s,""Night driving difficulty""),REGEXMATCH(s,""Glare/halos""))),""Overcorrect"",""Neutral""))))"),"Neutral") -> Neutral | T3: =LET(stab,G3,med,F3,sym,E3,IF(OR(stab="Unstable",med="High",sym="High"),"Conservative",IF(AND(stab="Stable",med="None",sym="None"),"Aggressive","Standard"))) -> Aggressive | U3: {=IF(T3="Conservative",XLOOKUP("max_delta_start_conservative",Calibration!B:B,Calibration!C:C),IF(T3="Standard",XLOOKUP("max_delta_start_standard",Calibration!B:B,Calibration!C:C),XLOOKUP("max_delta_start_aggressive",Calibration!B:B,Calibration!C:C)))} -> 2.5 | V3: {=XLOOKUP("max_delta_ar_standard",Calibration!B:B,Calibration!C:C)} -> 3 | W3: {=IF(AB3="Strict", XLOOKUP("axis_tol_strict",Calibration!$B:$B,Calibration!$C:$C), IF(AB3="Normal", XLOOKUP("axis_tol_normal",Calibration!$B:$B,Calibration!$C:$C), XLOOKUP("axis_tol_relaxed",Calibration!$B:$B,Calibration!$C:$C)))} -> 5 | X3: {=IF(T3="Aggressive", XLOOKUP("cyl_tol_aggressive",Calibration!$B:$B,Calibration!$C:$C), XLOOKUP("cyl_tol_standard",Calibration!$B:$B,Calibration!$C:$C))} -> 0.5 | Y3: {=IF(OR(E3="High",F3="High",XLOOKUP($A3,Patient_Input_Data!$B:$B,Patient_Input_Data!$AA:$AA,"")="True"),TRUE,FALSE)} -> FALSE | Z3: =IF(OR(G3<>"Stable",J3="Hybrid",H3="Large",I3="Large"),TRUE,FALSE) -> FALSE | AA3: =IF(AND(B3="Adult",G3="Stable",E3="None",F3="None"),"Fast",IF(OR(B3="Presbyope",G3<>"Stable",E3="High",F3="High"),"Slow","Normal")) -> Slow | AB3: =IF(OR(E3="High",F3="High",G3="Unstable"),"Strict",IF(OR(E3="Moderate",F3="Moderate",G3="Uncertain"),"Normal","Relaxed")) -> Relaxed | AC3: =IF(OR(G3<>"Stable",E3="High",F3="High"),"High",IF(OR(E3="Moderate",F3="Moderate"),"Medium","Low")) -> Low | AD3: =IF(OR(B3="Presbyope",G3="Unstable",F3="High",E3="High"),"Strong_Fog",IF(AND(B3="Adult",G3="Stable",OR(F3="Moderate",E3="Moderate")),"Standard_Fog","No_Fog")) -> Strong_Fog | AE3: {=IF(AD3="Strong_Fog",XLOOKUP("strong_fog_amount",Calibration!B:B,Calibration!C:C),IF(AD3="Standard_Fog",XLOOKUP("standard_fog_amount",Calibration!B:B,Calibration!C:C),XLOOKUP("no_fog_amount",Calibration!B:B,Calibration!C:C)))} -> 1 | AF3: =IF(AND(AD3="Strong_Fog",R3="6/9_acceptable"),"Early_Stop_if_Risk",IF(AD3="Strong_Fog","StepDown_0.25","StepDown_0.50_then_0.25")) -> StepDown_0.25 | AG3: =IF(OR(G3="Unstable",E3="High"),"High",IF(OR(E3="Moderate",F3="Moderate"),"Medium","Low")) -> Low | AH3: =IF(OR(E3="High",F3="High",G3="Unstable"),"Fine","Normal") -> Normal | AI3: {=IF(AB3="Strict", XLOOKUP("duochrome_max_flips_strict",Calibration!$B:$B,Calibration!$C:$C), IF(AB3="Normal", XLOOKUP("duochrome_max_flips_normal",Calibration!$B:$B,Calibration!$C:$C), XLOOKUP("duochrome_max_flips_relaxed",Calibration!$B:$B,Calibration!$C:$C)))} -> 5 | AJ3: {=LET( nearPr,D3, addExp,Q3, ageB,B3, forceHighNear,XLOOKUP("allow_high_near_priority_to_force_near",Calibration!$B:$B,Calibration!$C:$C), allowPossible,XLOOKUP("trigger_near_if_dv_add_expected_possible",Calibration!$B:$B,Calibration!$C:$C), allowLikely,XLOOKUP("trigger_near_if_dv_add_expected_likely",Calibration!$B:$B,Calibration!$C:$C), IF( OR( AND(addExp="Likely",allowLikely=TRUE), AND(addExp="Possible",allowPossible=TRUE), AND(nearPr="High",forceHighNear=TRUE) ), TRUE, FALSE ))} -> TRUE
A4: 3 | B4: {=LET(age,XLOOKUP($A4,Patient_Input_Data!$B:$B,Patient_Input_Data!$D:$D,""),childMax,XLOOKUP("age_child_max",Calibration!$B:$B,Calibration!$C:$C),presMin,XLOOKUP("age_presbyope_min",Calibration!$B:$B,Calibration!$C:$C),IF(age<childMax,"Child",IF(age>=presMin,"Presbyope","Adult")))} -> Adult | C4: {=LET(drive,XLOOKUP($A4,Patient_Input_Data!$B:$B,Patient_Input_Data!$I:$I,""),occ,XLOOKUP($A4,Patient_Input_Data!$B:$B,Patient_Input_Data!$G:$G,""),pri,XLOOKUP($A4,Patient_Input_Data!$B:$B,Patient_Input_Data!$AB:$AB,""),driveHigh,XLOOKUP("driving_hours_high",Calibration!$B:$B,Calibration!$C:$C),base,IF(OR(drive>=driveHigh,occ="Driver"),"High","Medium"),IF(pri="Comfort-first",IF(base="High","Medium","Low"),base))} -> Medium | D4: {=LET(np,XLOOKUP($A4,Patient_Input_Data!$B:$B,Patient_Input_Data!$AD:$AD,""),st,XLOOKUP($A4,Patient_Input_Data!$B:$B,Patient_Input_Data!$H:$H,""),rs,XLOOKUP($A4,Patient_Input_Data!$B:$B,Patient_Input_Data!$J:$J,""),screenHigh,XLOOKUP("screen_time_high",Calibration!$B:$B,Calibration!$C:$C),IF(np<>"",np,IF(OR(st>=screenHigh,rs="Blurred near"),"High","Medium")))} -> Low | E4: =IFERROR(__xludf.DUMMYFUNCTION("LET(s,XLOOKUP($A4,Patient_Input_Data!$B:$B,Patient_Input_Data!$K:$K,""""),IF(OR(REGEXMATCH(s,""Sudden vision change""),REGEXMATCH(s,""Double vision"")),""High"",IF(OR(REGEXMATCH(s,""Glare/halos""),REGEXMATCH(s,""Night driving difficulty""),REGEXMATCH(s,"""&"Fluctuating vision"")),""Moderate"",""None"")))"),"None") -> None | F4: {=LET(di,(XLOOKUP($A4,Patient_Input_Data!$B:$B,Patient_Input_Data!$U:$U,"")="True"),surg,XLOOKUP($A4,Patient_Input_Data!$B:$B,Patient_Input_Data!$X:$X,"")<>"None",ker,(XLOOKUP($A4,Patient_Input_Data!$B:$B,Patient_Input_Data!$Y:$Y,"")="True"),amb,(XLOOKUP($A4,Patient_Input_Data!$B:$B,Patient_Input_Data!$Z:$Z,"")="True"),inf,(XLOOKUP($A4,Patient_Input_Data!$B:$B,Patient_Input_Data!$AA:$AA,"")="True"),IF(OR(ker,inf),"High",IF(OR(di,surg,amb),"Moderate","None")))} -> None | G4: {=LET(last,XLOOKUP($A4,Patient_Input_Data!$B:$B,Patient_Input_Data!$Q:$Q,""),fl,(XLOOKUP($A4,Patient_Input_Data!$B:$B,Patient_Input_Data!$T:$T,"")="True"),chg,(XLOOKUP($A4,Patient_Input_Data!$B:$B,Patient_Input_Data!$S:$S,"")="True"),di,(XLOOKUP($A4,Patient_Input_Data!$B:$B,Patient_Input_Data!$U:$U,"")="True"),uncertainMonths,XLOOKUP("last_eye_test_uncertain_months",Calibration!$B:$B,Calibration!$C:$C),IF(OR(fl,chg),"Unstable",IF(OR(di,last>uncertainMonths),"Uncertain","Stable")))} -> Stable | H4: {=LET( arS,XLOOKUP($A4,AR_Input!$A:$A,AR_Input!$B:$B,""), arC,XLOOKUP($A4,AR_Input!$A:$A,AR_Input!$C:$C,""), arA,XLOOKUP($A4,AR_Input!$A:$A,AR_Input!$D:$D,""), lnS,XLOOKUP($A4,Lenso_Input!$A:$A,Lenso_Input!$B:$B,""), lnC,XLOOKUP($A4,Lenso_Input!$A:$A,Lenso_Input!$C:$C,""), lnA,XLOOKUP($A4,Lenso_Input!$A:$A,Lenso_Input!$D:$D,""), hasAR,AND(arS<>"",arC<>"",arA<>""), hasLenso,AND(lnS<>"",lnC<>"",lnA<>""), sMed,XLOOKUP("mismatch_re_sph_medium",Calibration!$B:$B,Calibration!$C:$C), sLarge,XLOOKUP("mismatch_re_sph_large",Calibration!$B:$B,Calibration!$C:$C), cMed,XLOOKUP("mismatch_re_cyl_medium",Calibration!$B:$B,Calibration!$C:$C), cLarge,XLOOKUP("mismatch_re_cyl_large",Calibration!$B:$B,Calibration!$C:$C), aMed,XLOOKUP("mismatch_re_axis_medium",Calibration!$B:$B,Calibration!$C:$C), aLarge,XLOOKUP("mismatch_re_axis_large",Calibration!$B:$B,Calibration!$C:$C), IF( NOT(AND(hasAR,hasLenso)), "Small", LET( dS,ABS(VALUE(arS)-VALUE(lnS)), dC,ABS(VALUE(arC)-VALUE(lnC)), dA,MIN(ABS(VALUE(arA)-VALUE(lnA)),180-ABS(VALUE(arA)-VALUE(lnA))), IF(OR(dS>sLarge,dC>cLarge,dA>aLarge),"Large",IF(OR(dS>sMed,dC>cMed,dA>aMed),"Medium","Small")) ) ))} -> Small | I4: {=LET( arS,XLOOKUP($A4,AR_Input!$A:$A,AR_Input!$E:$E,""), arC,XLOOKUP($A4,AR_Input!$A:$A,AR_Input!$F:$F,""), arA,XLOOKUP($A4,AR_Input!$A:$A,AR_Input!$G:$G,""), lnS,XLOOKUP($A4,Lenso_Input!$A:$A,Lenso_Input!$F:$F,""), lnC,XLOOKUP($A4,Lenso_Input!$A:$A,Lenso_Input!$G:$G,""), lnA,XLOOKUP($A4,Lenso_Input!$A:$A,Lenso_Input!$H:$H,""), hasAR,AND(arS<>"",arC<>"",arA<>""), hasLenso,AND(lnS<>"",lnC<>"",lnA<>""), sMed,XLOOKUP("mismatch_le_sph_medium",Calibration!$B:$B,Calibration!$C:$C), sLarge,XLOOKUP("mismatch_le_sph_large",Calibration!$B:$B,Calibration!$C:$C), cMed,XLOOKUP("mismatch_le_cyl_medium",Calibration!$B:$B,Calibration!$C:$C), cLarge,XLOOKUP("mismatch_le_cyl_large",Calibration!$B:$B,Calibration!$C:$C), aMed,XLOOKUP("mismatch_le_axis_medium",Calibration!$B:$B,Calibration!$C:$C), aLarge,XLOOKUP("mismatch_le_axis_large",Calibration!$B:$B,Calibration!$C:$C), IF( NOT(AND(hasAR,hasLenso)), "Small", LET( dS,ABS(VALUE(arS)-VALUE(lnS)), dC,ABS(VALUE(arC)-VALUE(lnC)), dA,MIN(ABS(VALUE(arA)-VALUE(lnA)),180-ABS(VALUE(arA)-VALUE(lnA))), IF(OR(dS>sLarge,dC>cLarge,dA>aLarge),"Large",IF(OR(dS>sMed,dC>cMed,dA>aMed),"Medium","Small")) ) ))} -> Large | J4: {=LET(sat,XLOOKUP($A4,Patient_Input_Data!$B:$B,Patient_Input_Data!$O:$O,""),rs,XLOOKUP($A4,Patient_Input_Data!$B:$B,Patient_Input_Data!$J:$J,""),stab,$G4,misR,$H4,misL,$I4,startAR,XLOOKUP("start_policy_if_only_ar",Calibration!$B:$B,Calibration!$C:$C),startL,XLOOKUP("start_policy_if_only_lenso",Calibration!$B:$B,Calibration!$C:$C),startSat,XLOOKUP("start_policy_if_satisfied_small_mismatch",Calibration!$B:$B,Calibration!$C:$C),startUnsat,XLOOKUP("start_policy_if_unsatisfied_or_blur",Calibration!$B:$B,Calibration!$C:$C),startHybrid,XLOOKUP("start_policy_if_large_mismatch_or_unstable",Calibration!$B:$B,Calibration!$C:$C),arR,XLOOKUP($A4,AR_Input!$A:$A,AR_Input!$B:$B,""),arL,XLOOKUP($A4,AR_Input!$A:$A,AR_Input!$E:$E,""),lenR,XLOOKUP($A4,Lenso_Input!$A:$A,Lenso_Input!$B:$B,""),lenL,XLOOKUP($A4,Lenso_Input!$A:$A,Lenso_Input!$F:$F,""),hasAR,OR(arR<>"",arL<>""),hasLenso,OR(lenR<>"",lenL<>""),IF(AND(hasAR,NOT(hasLenso)),startAR,IF(AND(hasLenso,NOT(hasAR)),startL,IF(AND(sat="Satisfied",misR="Small",misL="Small"),startSat,IF(OR(sat="Not satisfied",rs="Blurred distance",rs="Blurred near"),startUnsat,IF(OR(misR="Large",misL="Large",stab="Unstable"),startHybrid,startAR))))))} -> Hybrid | K4: {=LET(ar,XLOOKUP($A4,AR_Input!$A:$A,AR_Input!$B:$B,""),ln,XLOOKUP($A4,Lenso_Input!$A:$A,Lenso_Input!$B:$B,""),pol,$J4,step,XLOOKUP("hybrid_rounding_step",Calibration!$B:$B,Calibration!$C:$C),IF(pol="Start_AR",ar,IF(pol="Start_Lenso",IF(ln<>"",ln,ar),IF(AND(ar<>"",ln<>""),ROUND(((ar+ln)/2)/step,0)*step,IF(ar<>"",ar,ln)))))} -> -2.25 | L4: {=LET(ar,XLOOKUP($A4,AR_Input!$A:$A,AR_Input!$C:$C,""),ln,XLOOKUP($A4,Lenso_Input!$A:$A,Lenso_Input!$C:$C,""),pol,$J4,step,XLOOKUP("hybrid_rounding_step",Calibration!$B:$B,Calibration!$C:$C),IF(pol="Start_AR",ar,IF(pol="Start_Lenso",IF(ln<>"",ln,ar),IF(AND(ar<>"",ln<>""),ROUND(((ar+ln)/2)/step,0)*step,IF(ar<>"",ar,ln)))))} -> -1 | M4: {=LET(ar,XLOOKUP($A4,AR_Input!$A:$A,AR_Input!$D:$D,""),ln,XLOOKUP($A4,Lenso_Input!$A:$A,Lenso_Input!$D:$D,""),pol,$J4,IF(pol="Start_AR",ar,IF(pol="Start_Lenso",IF(ln<>"",ln,ar),IF(ar<>"",ar,ln))))} -> 80 | N4: {=LET(ar,XLOOKUP($A4,AR_Input!$A:$A,AR_Input!$E:$E,""),ln,XLOOKUP($A4,Lenso_Input!$A:$A,Lenso_Input!$F:$F,""),pol,$J4,step,XLOOKUP("hybrid_rounding_step",Calibration!$B:$B,Calibration!$C:$C),IF(pol="Start_AR",ar,IF(pol="Start_Lenso",IF(ln<>"",ln,ar),IF(AND(ar<>"",ln<>""),ROUND(((ar+ln)/2)/step,0)*step,IF(ar<>"",ar,ln)))))} -> -3.75 | O4: {=LET(ar,XLOOKUP($A4,AR_Input!$A:$A,AR_Input!$F:$F,""),ln,XLOOKUP($A4,Lenso_Input!$A:$A,Lenso_Input!$G:$G,""),pol,$J4,step,XLOOKUP("hybrid_rounding_step",Calibration!$B:$B,Calibration!$C:$C),IF(pol="Start_AR",ar,IF(pol="Start_Lenso",IF(ln<>"",ln,ar),IF(AND(ar<>"",ln<>""),ROUND(((ar+ln)/2)/step,0)*step,IF(ar<>"",ar,ln)))))} -> -0.25 | P4: {=LET(ar,XLOOKUP($A4,AR_Input!$A:$A,AR_Input!$G:$G,""),ln,XLOOKUP($A4,Lenso_Input!$A:$A,Lenso_Input!$H:$H,""),pol,$J4,IF(pol="Start_AR",ar,IF(pol="Start_Lenso",IF(ln<>"",ln,ar),IF(ar<>"",ar,ln))))} -> 40 | Q4: {=LET(a,XLOOKUP($A4,Patient_Input_Data!$B:$B,Patient_Input_Data!$D:$D,""),wt,XLOOKUP($A4,Patient_Input_Data!$B:$B,Patient_Input_Data!$M:$M,""),addR,XLOOKUP($A4,Lenso_Input!$A:$A,Lenso_Input!$E:$E,""),addL,XLOOKUP($A4,Lenso_Input!$A:$A,Lenso_Input!$I:$I,""),near,D4,likelyAge,XLOOKUP("add_likely_min_age",Calibration!$B:$B,Calibration!$C:$C),possibleAge,XLOOKUP("add_possible_min_age",Calibration!$B:$B,Calibration!$C:$C),IF(OR(a>=likelyAge,wt="Progressive",wt="Bifocal",addR<>"",addL<>""),"Likely",IF(AND(a>=possibleAge,a<=likelyAge-1,near="High"),"Possible","None")))} -> None | R4: {=LET(dt,XLOOKUP($A4,Patient_Input_Data!$B:$B,Patient_Input_Data!$AC:$AC,""),sym,E4,med,F4,stab,G4,target66,XLOOKUP("default_distance_target",Calibration!$B:$B,Calibration!$C:$C),target69,XLOOKUP("high_risk_distance_target",Calibration!$B:$B,Calibration!$C:$C),IF(dt<>"",IF(OR(dt="Accept 6/9 if needed",dt="6/9 acceptable",dt="6/9_acceptable"),target69,target66),IF(OR(sym="High",med="High",stab="Unstable"),target69,target66)))} -> 6/6_target | S4: =IFERROR(__xludf.DUMMYFUNCTION("LET(pri,XLOOKUP($A4,Patient_Input_Data!$B:$B,Patient_Input_Data!$AB:$AB,""""),ageB,B4,near,D4,oc,XLOOKUP($A4,Patient_Input_Data!$B:$B,Patient_Input_Data!$G:$G,""""),sym,E4,s,XLOOKUP($A4,Patient_Input_Data!$B:$B,Patient_Input_Data!$K:$K,""""),IF(sym=""High"&""",""Neutral"",IF(AND(pri=""Comfort-first"",ageB=""Presbyope"",near=""High""),""Undercorrect"",IF(AND(oc=""Driver"",OR(REGEXMATCH(s,""Night driving difficulty""),REGEXMATCH(s,""Glare/halos""))),""Overcorrect"",""Neutral""))))"),"Neutral") -> Neutral | T4: =LET(stab,G4,med,F4,sym,E4,IF(OR(stab="Unstable",med="High",sym="High"),"Conservative",IF(AND(stab="Stable",med="None",sym="None"),"Aggressive","Standard"))) -> Aggressive | U4: {=IF(T4="Conservative",XLOOKUP("max_delta_start_conservative",Calibration!B:B,Calibration!C:C),IF(T4="Standard",XLOOKUP("max_delta_start_standard",Calibration!B:B,Calibration!C:C),XLOOKUP("max_delta_start_aggressive",Calibration!B:B,Calibration!C:C)))} -> 2.5 | V4: {=XLOOKUP("max_delta_ar_standard",Calibration!B:B,Calibration!C:C)} -> 3 | W4: {=IF(AB4="Strict", XLOOKUP("axis_tol_strict",Calibration!$B:$B,Calibration!$C:$C), IF(AB4="Normal", XLOOKUP("axis_tol_normal",Calibration!$B:$B,Calibration!$C:$C), XLOOKUP("axis_tol_relaxed",Calibration!$B:$B,Calibration!$C:$C)))} -> 5 | X4: {=IF(T4="Aggressive", XLOOKUP("cyl_tol_aggressive",Calibration!$B:$B,Calibration!$C:$C), XLOOKUP("cyl_tol_standard",Calibration!$B:$B,Calibration!$C:$C))} -> 0.5 | Y4: {=IF(OR(E4="High",F4="High",XLOOKUP($A4,Patient_Input_Data!$B:$B,Patient_Input_Data!$AA:$AA,"")="True"),TRUE,FALSE)} -> FALSE | Z4: =IF(OR(G4<>"Stable",J4="Hybrid",H4="Large",I4="Large"),TRUE,FALSE) -> TRUE | AA4: =IF(AND(B4="Adult",G4="Stable",E4="None",F4="None"),"Fast",IF(OR(B4="Presbyope",G4<>"Stable",E4="High",F4="High"),"Slow","Normal")) -> Fast | AB4: =IF(OR(E4="High",F4="High",G4="Unstable"),"Strict",IF(OR(E4="Moderate",F4="Moderate",G4="Uncertain"),"Normal","Relaxed")) -> Relaxed | AC4: =IF(OR(G4<>"Stable",E4="High",F4="High"),"High",IF(OR(E4="Moderate",F4="Moderate"),"Medium","Low")) -> Low | AD4: =IF(OR(B4="Presbyope",G4="Unstable",F4="High",E4="High"),"Strong_Fog",IF(AND(B4="Adult",G4="Stable",OR(F4="Moderate",E4="Moderate")),"Standard_Fog","No_Fog")) -> No_Fog | AE4: {=IF(AD4="Strong_Fog",XLOOKUP("strong_fog_amount",Calibration!B:B,Calibration!C:C),IF(AD4="Standard_Fog",XLOOKUP("standard_fog_amount",Calibration!B:B,Calibration!C:C),XLOOKUP("no_fog_amount",Calibration!B:B,Calibration!C:C)))} -> 0.25 | AF4: =IF(AND(AD4="Strong_Fog",R4="6/9_acceptable"),"Early_Stop_if_Risk",IF(AD4="Strong_Fog","StepDown_0.25","StepDown_0.50_then_0.25")) -> StepDown_0.50_then_0.25 | AG4: =IF(OR(G4="Unstable",E4="High"),"High",IF(OR(E4="Moderate",F4="Moderate"),"Medium","Low")) -> Low | AH4: =IF(OR(E4="High",F4="High",G4="Unstable"),"Fine","Normal") -> Normal | AI4: {=IF(AB4="Strict", XLOOKUP("duochrome_max_flips_strict",Calibration!$B:$B,Calibration!$C:$C), IF(AB4="Normal", XLOOKUP("duochrome_max_flips_normal",Calibration!$B:$B,Calibration!$C:$C), XLOOKUP("duochrome_max_flips_relaxed",Calibration!$B:$B,Calibration!$C:$C)))} -> 5 | AJ4: {=LET( nearPr,D4, addExp,Q4, ageB,B4, forceHighNear,XLOOKUP("allow_high_near_priority_to_force_near",Calibration!$B:$B,Calibration!$C:$C), allowPossible,XLOOKUP("trigger_near_if_dv_add_expected_possible",Calibration!$B:$B,Calibration!$C:$C), allowLikely,XLOOKUP("trigger_near_if_dv_add_expected_likely",Calibration!$B:$B,Calibration!$C:$C), IF( OR( AND(addExp="Likely",allowLikely=TRUE), AND(addExp="Possible",allowPossible=TRUE), AND(nearPr="High",forceHighNear=TRUE) ), TRUE, FALSE ))} -> FALSE
A5: 4 | B5: {=LET(age,XLOOKUP($A5,Patient_Input_Data!$B:$B,Patient_Input_Data!$D:$D,""),childMax,XLOOKUP("age_child_max",Calibration!$B:$B,Calibration!$C:$C),presMin,XLOOKUP("age_presbyope_min",Calibration!$B:$B,Calibration!$C:$C),IF(age<childMax,"Child",IF(age>=presMin,"Presbyope","Adult")))} -> Adult | C5: {=LET(drive,XLOOKUP($A5,Patient_Input_Data!$B:$B,Patient_Input_Data!$I:$I,""),occ,XLOOKUP($A5,Patient_Input_Data!$B:$B,Patient_Input_Data!$G:$G,""),pri,XLOOKUP($A5,Patient_Input_Data!$B:$B,Patient_Input_Data!$AB:$AB,""),driveHigh,XLOOKUP("driving_hours_high",Calibration!$B:$B,Calibration!$C:$C),base,IF(OR(drive>=driveHigh,occ="Driver"),"High","Medium"),IF(pri="Comfort-first",IF(base="High","Medium","Low"),base))} -> Medium | D5: {=LET(np,XLOOKUP($A5,Patient_Input_Data!$B:$B,Patient_Input_Data!$AD:$AD,""),st,XLOOKUP($A5,Patient_Input_Data!$B:$B,Patient_Input_Data!$H:$H,""),rs,XLOOKUP($A5,Patient_Input_Data!$B:$B,Patient_Input_Data!$J:$J,""),screenHigh,XLOOKUP("screen_time_high",Calibration!$B:$B,Calibration!$C:$C),IF(np<>"",np,IF(OR(st>=screenHigh,rs="Blurred near"),"High","Medium")))} -> High | E5: =IFERROR(__xludf.DUMMYFUNCTION("LET(s,XLOOKUP($A5,Patient_Input_Data!$B:$B,Patient_Input_Data!$K:$K,""""),IF(OR(REGEXMATCH(s,""Sudden vision change""),REGEXMATCH(s,""Double vision"")),""High"",IF(OR(REGEXMATCH(s,""Glare/halos""),REGEXMATCH(s,""Night driving difficulty""),REGEXMATCH(s,"""&"Fluctuating vision"")),""Moderate"",""None"")))"),"None") -> None | F5: {=LET(di,(XLOOKUP($A5,Patient_Input_Data!$B:$B,Patient_Input_Data!$U:$U,"")="True"),surg,XLOOKUP($A5,Patient_Input_Data!$B:$B,Patient_Input_Data!$X:$X,"")<>"None",ker,(XLOOKUP($A5,Patient_Input_Data!$B:$B,Patient_Input_Data!$Y:$Y,"")="True"),amb,(XLOOKUP($A5,Patient_Input_Data!$B:$B,Patient_Input_Data!$Z:$Z,"")="True"),inf,(XLOOKUP($A5,Patient_Input_Data!$B:$B,Patient_Input_Data!$AA:$AA,"")="True"),IF(OR(ker,inf),"High",IF(OR(di,surg,amb),"Moderate","None")))} -> None | G5: {=LET(last,XLOOKUP($A5,Patient_Input_Data!$B:$B,Patient_Input_Data!$Q:$Q,""),fl,(XLOOKUP($A5,Patient_Input_Data!$B:$B,Patient_Input_Data!$T:$T,"")="True"),chg,(XLOOKUP($A5,Patient_Input_Data!$B:$B,Patient_Input_Data!$S:$S,"")="True"),di,(XLOOKUP($A5,Patient_Input_Data!$B:$B,Patient_Input_Data!$U:$U,"")="True"),uncertainMonths,XLOOKUP("last_eye_test_uncertain_months",Calibration!$B:$B,Calibration!$C:$C),IF(OR(fl,chg),"Unstable",IF(OR(di,last>uncertainMonths),"Uncertain","Stable")))} -> Stable | H5: {=LET( arS,XLOOKUP($A5,AR_Input!$A:$A,AR_Input!$B:$B,""), arC,XLOOKUP($A5,AR_Input!$A:$A,AR_Input!$C:$C,""), arA,XLOOKUP($A5,AR_Input!$A:$A,AR_Input!$D:$D,""), lnS,XLOOKUP($A5,Lenso_Input!$A:$A,Lenso_Input!$B:$B,""), lnC,XLOOKUP($A5,Lenso_Input!$A:$A,Lenso_Input!$C:$C,""), lnA,XLOOKUP($A5,Lenso_Input!$A:$A,Lenso_Input!$D:$D,""), hasAR,AND(arS<>"",arC<>"",arA<>""), hasLenso,AND(lnS<>"",lnC<>"",lnA<>""), sMed,XLOOKUP("mismatch_re_sph_medium",Calibration!$B:$B,Calibration!$C:$C), sLarge,XLOOKUP("mismatch_re_sph_large",Calibration!$B:$B,Calibration!$C:$C), cMed,XLOOKUP("mismatch_re_cyl_medium",Calibration!$B:$B,Calibration!$C:$C), cLarge,XLOOKUP("mismatch_re_cyl_large",Calibration!$B:$B,Calibration!$C:$C), aMed,XLOOKUP("mismatch_re_axis_medium",Calibration!$B:$B,Calibration!$C:$C), aLarge,XLOOKUP("mismatch_re_axis_large",Calibration!$B:$B,Calibration!$C:$C), IF( NOT(AND(hasAR,hasLenso)), "Small", LET( dS,ABS(VALUE(arS)-VALUE(lnS)), dC,ABS(VALUE(arC)-VALUE(lnC)), dA,MIN(ABS(VALUE(arA)-VALUE(lnA)),180-ABS(VALUE(arA)-VALUE(lnA))), IF(OR(dS>sLarge,dC>cLarge,dA>aLarge),"Large",IF(OR(dS>sMed,dC>cMed,dA>aMed),"Medium","Small")) ) ))} -> Small | I5: {=LET( arS,XLOOKUP($A5,AR_Input!$A:$A,AR_Input!$E:$E,""), arC,XLOOKUP($A5,AR_Input!$A:$A,AR_Input!$F:$F,""), arA,XLOOKUP($A5,AR_Input!$A:$A,AR_Input!$G:$G,""), lnS,XLOOKUP($A5,Lenso_Input!$A:$A,Lenso_Input!$F:$F,""), lnC,XLOOKUP($A5,Lenso_Input!$A:$A,Lenso_Input!$G:$G,""), lnA,XLOOKUP($A5,Lenso_Input!$A:$A,Lenso_Input!$H:$H,""), hasAR,AND(arS<>"",arC<>"",arA<>""), hasLenso,AND(lnS<>"",lnC<>"",lnA<>""), sMed,XLOOKUP("mismatch_le_sph_medium",Calibration!$B:$B,Calibration!$C:$C), sLarge,XLOOKUP("mismatch_le_sph_large",Calibration!$B:$B,Calibration!$C:$C), cMed,XLOOKUP("mismatch_le_cyl_medium",Calibration!$B:$B,Calibration!$C:$C), cLarge,XLOOKUP("mismatch_le_cyl_large",Calibration!$B:$B,Calibration!$C:$C), aMed,XLOOKUP("mismatch_le_axis_medium",Calibration!$B:$B,Calibration!$C:$C), aLarge,XLOOKUP("mismatch_le_axis_large",Calibration!$B:$B,Calibration!$C:$C), IF( NOT(AND(hasAR,hasLenso)), "Small", LET( dS,ABS(VALUE(arS)-VALUE(lnS)), dC,ABS(VALUE(arC)-VALUE(lnC)), dA,MIN(ABS(VALUE(arA)-VALUE(lnA)),180-ABS(VALUE(arA)-VALUE(lnA))), IF(OR(dS>sLarge,dC>cLarge,dA>aLarge),"Large",IF(OR(dS>sMed,dC>cMed,dA>aMed),"Medium","Small")) ) ))} -> Small | J5: {=LET(sat,XLOOKUP($A5,Patient_Input_Data!$B:$B,Patient_Input_Data!$O:$O,""),rs,XLOOKUP($A5,Patient_Input_Data!$B:$B,Patient_Input_Data!$J:$J,""),stab,$G5,misR,$H5,misL,$I5,startAR,XLOOKUP("start_policy_if_only_ar",Calibration!$B:$B,Calibration!$C:$C),startL,XLOOKUP("start_policy_if_only_lenso",Calibration!$B:$B,Calibration!$C:$C),startSat,XLOOKUP("start_policy_if_satisfied_small_mismatch",Calibration!$B:$B,Calibration!$C:$C),startUnsat,XLOOKUP("start_policy_if_unsatisfied_or_blur",Calibration!$B:$B,Calibration!$C:$C),startHybrid,XLOOKUP("start_policy_if_large_mismatch_or_unstable",Calibration!$B:$B,Calibration!$C:$C),arR,XLOOKUP($A5,AR_Input!$A:$A,AR_Input!$B:$B,""),arL,XLOOKUP($A5,AR_Input!$A:$A,AR_Input!$E:$E,""),lenR,XLOOKUP($A5,Lenso_Input!$A:$A,Lenso_Input!$B:$B,""),lenL,XLOOKUP($A5,Lenso_Input!$A:$A,Lenso_Input!$F:$F,""),hasAR,OR(arR<>"",arL<>""),hasLenso,OR(lenR<>"",lenL<>""),IF(AND(hasAR,NOT(hasLenso)),startAR,IF(AND(hasLenso,NOT(hasAR)),startL,IF(AND(sat="Satisfied",misR="Small",misL="Small"),startSat,IF(OR(sat="Not satisfied",rs="Blurred distance",rs="Blurred near"),startUnsat,IF(OR(misR="Large",misL="Large",stab="Unstable"),startHybrid,startAR))))))} -> Start_Lenso | K5: {=LET(ar,XLOOKUP($A5,AR_Input!$A:$A,AR_Input!$B:$B,""),ln,XLOOKUP($A5,Lenso_Input!$A:$A,Lenso_Input!$B:$B,""),pol,$J5,step,XLOOKUP("hybrid_rounding_step",Calibration!$B:$B,Calibration!$C:$C),IF(pol="Start_AR",ar,IF(pol="Start_Lenso",IF(ln<>"",ln,ar),IF(AND(ar<>"",ln<>""),ROUND(((ar+ln)/2)/step,0)*step,IF(ar<>"",ar,ln)))))} -> -3.5 | L5: {=LET(ar,XLOOKUP($A5,AR_Input!$A:$A,AR_Input!$C:$C,""),ln,XLOOKUP($A5,Lenso_Input!$A:$A,Lenso_Input!$C:$C,""),pol,$J5,step,XLOOKUP("hybrid_rounding_step",Calibration!$B:$B,Calibration!$C:$C),IF(pol="Start_AR",ar,IF(pol="Start_Lenso",IF(ln<>"",ln,ar),IF(AND(ar<>"",ln<>""),ROUND(((ar+ln)/2)/step,0)*step,IF(ar<>"",ar,ln)))))} -> -2 | M5: {=LET(ar,XLOOKUP($A5,AR_Input!$A:$A,AR_Input!$D:$D,""),ln,XLOOKUP($A5,Lenso_Input!$A:$A,Lenso_Input!$D:$D,""),pol,$J5,IF(pol="Start_AR",ar,IF(pol="Start_Lenso",IF(ln<>"",ln,ar),IF(ar<>"",ar,ln))))} -> 10 | N5: {=LET(ar,XLOOKUP($A5,AR_Input!$A:$A,AR_Input!$E:$E,""),ln,XLOOKUP($A5,Lenso_Input!$A:$A,Lenso_Input!$F:$F,""),pol,$J5,step,XLOOKUP("hybrid_rounding_step",Calibration!$B:$B,Calibration!$C:$C),IF(pol="Start_AR",ar,IF(pol="Start_Lenso",IF(ln<>"",ln,ar),IF(AND(ar<>"",ln<>""),ROUND(((ar+ln)/2)/step,0)*step,IF(ar<>"",ar,ln)))))} -> -3.25 | O5: {=LET(ar,XLOOKUP($A5,AR_Input!$A:$A,AR_Input!$F:$F,""),ln,XLOOKUP($A5,Lenso_Input!$A:$A,Lenso_Input!$G:$G,""),pol,$J5,step,XLOOKUP("hybrid_rounding_step",Calibration!$B:$B,Calibration!$C:$C),IF(pol="Start_AR",ar,IF(pol="Start_Lenso",IF(ln<>"",ln,ar),IF(AND(ar<>"",ln<>""),ROUND(((ar+ln)/2)/step,0)*step,IF(ar<>"",ar,ln)))))} -> -2 | P5: {=LET(ar,XLOOKUP($A5,AR_Input!$A:$A,AR_Input!$G:$G,""),ln,XLOOKUP($A5,Lenso_Input!$A:$A,Lenso_Input!$H:$H,""),pol,$J5,IF(pol="Start_AR",ar,IF(pol="Start_Lenso",IF(ln<>"",ln,ar),IF(ar<>"",ar,ln))))} -> 170 | Q5: {=LET(a,XLOOKUP($A5,Patient_Input_Data!$B:$B,Patient_Input_Data!$D:$D,""),wt,XLOOKUP($A5,Patient_Input_Data!$B:$B,Patient_Input_Data!$M:$M,""),addR,XLOOKUP($A5,Lenso_Input!$A:$A,Lenso_Input!$E:$E,""),addL,XLOOKUP($A5,Lenso_Input!$A:$A,Lenso_Input!$I:$I,""),near,D5,likelyAge,XLOOKUP("add_likely_min_age",Calibration!$B:$B,Calibration!$C:$C),possibleAge,XLOOKUP("add_possible_min_age",Calibration!$B:$B,Calibration!$C:$C),IF(OR(a>=likelyAge,wt="Progressive",wt="Bifocal",addR<>"",addL<>""),"Likely",IF(AND(a>=possibleAge,a<=likelyAge-1,near="High"),"Possible","None")))} -> None | R5: {=LET(dt,XLOOKUP($A5,Patient_Input_Data!$B:$B,Patient_Input_Data!$AC:$AC,""),sym,E5,med,F5,stab,G5,target66,XLOOKUP("default_distance_target",Calibration!$B:$B,Calibration!$C:$C),target69,XLOOKUP("high_risk_distance_target",Calibration!$B:$B,Calibration!$C:$C),IF(dt<>"",IF(OR(dt="Accept 6/9 if needed",dt="6/9 acceptable",dt="6/9_acceptable"),target69,target66),IF(OR(sym="High",med="High",stab="Unstable"),target69,target66)))} -> 6/6_target | S5: =IFERROR(__xludf.DUMMYFUNCTION("LET(pri,XLOOKUP($A5,Patient_Input_Data!$B:$B,Patient_Input_Data!$AB:$AB,""""),ageB,B5,near,D5,oc,XLOOKUP($A5,Patient_Input_Data!$B:$B,Patient_Input_Data!$G:$G,""""),sym,E5,s,XLOOKUP($A5,Patient_Input_Data!$B:$B,Patient_Input_Data!$K:$K,""""),IF(sym=""High"&""",""Neutral"",IF(AND(pri=""Comfort-first"",ageB=""Presbyope"",near=""High""),""Undercorrect"",IF(AND(oc=""Driver"",OR(REGEXMATCH(s,""Night driving difficulty""),REGEXMATCH(s,""Glare/halos""))),""Overcorrect"",""Neutral""))))"),"Neutral") -> Neutral | T5: =LET(stab,G5,med,F5,sym,E5,IF(OR(stab="Unstable",med="High",sym="High"),"Conservative",IF(AND(stab="Stable",med="None",sym="None"),"Aggressive","Standard"))) -> Aggressive | U5: {=IF(T5="Conservative",XLOOKUP("max_delta_start_conservative",Calibration!B:B,Calibration!C:C),IF(T5="Standard",XLOOKUP("max_delta_start_standard",Calibration!B:B,Calibration!C:C),XLOOKUP("max_delta_start_aggressive",Calibration!B:B,Calibration!C:C)))} -> 2.5 | V5: {=XLOOKUP("max_delta_ar_standard",Calibration!B:B,Calibration!C:C)} -> 3 | W5: {=IF(AB5="Strict", XLOOKUP("axis_tol_strict",Calibration!$B:$B,Calibration!$C:$C), IF(AB5="Normal", XLOOKUP("axis_tol_normal",Calibration!$B:$B,Calibration!$C:$C), XLOOKUP("axis_tol_relaxed",Calibration!$B:$B,Calibration!$C:$C)))} -> 5 | X5: {=IF(T5="Aggressive", XLOOKUP("cyl_tol_aggressive",Calibration!$B:$B,Calibration!$C:$C), XLOOKUP("cyl_tol_standard",Calibration!$B:$B,Calibration!$C:$C))} -> 0.5 | Y5: {=IF(OR(E5="High",F5="High",XLOOKUP($A5,Patient_Input_Data!$B:$B,Patient_Input_Data!$AA:$AA,"")="True"),TRUE,FALSE)} -> FALSE | Z5: =IF(OR(G5<>"Stable",J5="Hybrid",H5="Large",I5="Large"),TRUE,FALSE) -> FALSE | AA5: =IF(AND(B5="Adult",G5="Stable",E5="None",F5="None"),"Fast",IF(OR(B5="Presbyope",G5<>"Stable",E5="High",F5="High"),"Slow","Normal")) -> Fast | AB5: =IF(OR(E5="High",F5="High",G5="Unstable"),"Strict",IF(OR(E5="Moderate",F5="Moderate",G5="Uncertain"),"Normal","Relaxed")) -> Relaxed | AC5: =IF(OR(G5<>"Stable",E5="High",F5="High"),"High",IF(OR(E5="Moderate",F5="Moderate"),"Medium","Low")) -> Low | AD5: =IF(OR(B5="Presbyope",G5="Unstable",F5="High",E5="High"),"Strong_Fog",IF(AND(B5="Adult",G5="Stable",OR(F5="Moderate",E5="Moderate")),"Standard_Fog","No_Fog")) -> No_Fog | AE5: {=IF(AD5="Strong_Fog",XLOOKUP("strong_fog_amount",Calibration!B:B,Calibration!C:C),IF(AD5="Standard_Fog",XLOOKUP("standard_fog_amount",Calibration!B:B,Calibration!C:C),XLOOKUP("no_fog_amount",Calibration!B:B,Calibration!C:C)))} -> 0.25 | AF5: =IF(AND(AD5="Strong_Fog",R5="6/9_acceptable"),"Early_Stop_if_Risk",IF(AD5="Strong_Fog","StepDown_0.25","StepDown_0.50_then_0.25")) -> StepDown_0.50_then_0.25 | AG5: =IF(OR(G5="Unstable",E5="High"),"High",IF(OR(E5="Moderate",F5="Moderate"),"Medium","Low")) -> Low | AH5: =IF(OR(E5="High",F5="High",G5="Unstable"),"Fine","Normal") -> Normal | AI5: {=IF(AB5="Strict", XLOOKUP("duochrome_max_flips_strict",Calibration!$B:$B,Calibration!$C:$C), IF(AB5="Normal", XLOOKUP("duochrome_max_flips_normal",Calibration!$B:$B,Calibration!$C:$C), XLOOKUP("duochrome_max_flips_relaxed",Calibration!$B:$B,Calibration!$C:$C)))} -> 5 | AJ5: {=LET( nearPr,D5, addExp,Q5, ageB,B5, forceHighNear,XLOOKUP("allow_high_near_priority_to_force_near",Calibration!$B:$B,Calibration!$C:$C), allowPossible,XLOOKUP("trigger_near_if_dv_add_expected_possible",Calibration!$B:$B,Calibration!$C:$C), allowLikely,XLOOKUP("trigger_near_if_dv_add_expected_likely",Calibration!$B:$B,Calibration!$C:$C), IF( OR( AND(addExp="Likely",allowLikely=TRUE), AND(addExp="Possible",allowPossible=TRUE), AND(nearPr="High",forceHighNear=TRUE) ), TRUE, FALSE ))} -> TRUE
